Workbook

Sheet Cover
B2: DULCINEA
B3: Portfolio Investment Model — Medellín & El Retiro, Colombia
B4: =TEXT(Input!$C$57,"0")&"-year buy · remodel · rent · sell fund · USD · TRM COP "&TEXT(Input!$C$5,"#,##0")&" per USD (reference) · Model start "&TEXT(Input!$C$7,"mmm yyyy") -> 4-year buy · remodel · rent · sell fund · USD · TRM COP 3,090 per USD (reference) · Model start Oct 2026
B5: Color Coding
B6: Hardcoded input — Input tab levers; Properties deal terms; ServCo cost & comp tabs; sensitivity steps on Portfolio Analysis & Portfolio Analysis. Nowhere else.
B7: Formula calculated on the same sheet — never overwrite
B8: Link pulling from another sheet in this workbook — trace to its source tab before changing anything
B9: Key result / subtotal row (light-blue fill); navy bands are section headers
B10: Guidance verdicts — automatic traffic lights vs researched benchmarks: green within range · yellow below · red above
B11: Zeros display as “–”; negatives in (parentheses); all amounts USD unless marked COP
B12: Workbook Guide
B14: Business Description | C14: What Dulcinea I is, how it makes money, the Equity Investor Kickers, structure and key risks — in plain language, no numbers
B15: Dashboard | C15: Start here for the numbers: Equity Investor results first, then the kickers, value creation, STR operations, taxes and the charts
B16: The Buy Box | C16: The criteria a property must meet to enter the fund, the live check of the five properties, and the sourcing funnel
B17: Input | C17: Every assumption in one place — FX, exit and rental drivers, costs, Colombian taxes, per-property inputs, capital terms — plus the model checks
B18: Income Statement | C18: Contribution-margin statement by property: revenue, variable costs, contribution margin, fixed costs, taxes and net income
B19: Balance Sheet / Statement of Cash Flows | C19: Integrated statements with balance and cash tie-out checks every year
B20: Investor Return | C20: Equity Investor capital calls, distributions and carry, with MOIC, IRR (on dated monthly cash flows) and payback
B21: Properties / Property Detail | C21: Deal-by-deal underwriting and per-property annual income and expenses
B22: Portfolio Analysis / Sources & Uses | C22: Exit and hold-period sensitivities, deal-level returns, cap-rate analysis and capital deployment
B23: ServCo Financials | C23: ServCo's fees to the fund, benchmarked, with time-based executive allocation
B24: Medellín Market Data | C24: Official DANE price series and the USD/COP reference, cross-checked against the model's appreciation assumption
B25: Lola & Ber / Glossary | C25: The hospitality brand associated with Dulcinea, and definitions of every term (including Colombian taxes, in Spanish with legal references)
B26: Working tabs (_ prefix) | C26: _Month Engine (monthly cash-flow engine) · _Seasonality (STR pricing and seasonality) · _IRR Engine (dated flows behind every IRR) · _Forced Assumptions · _ICP Archive · _Handoff
B27: Confidential
B29: Prepared for internal use and qualified investors. Contains proprietary assumptions and negotiated pricing. Do not distribute without authorization.

Sheet Dashboard
B1: Dulcinea — Dashboard | G1: =Input!$C$146 -> ALL CHECKS PASS
B2: =TEXT(Input!$C$57,"0")&"-year program (through final exit) · USD · TRM COP "&TEXT(Input!$C$5,"#,##0")&" per USD · Model start "&TEXT(Input!$C$7,"mmm yyyy") -> 4-year program (through final exit) · USD · TRM COP 3,090 per USD · Model start Oct 2026
B4: 1. Equity Investor Results
B5: Equity Investor IRR (net of fees, tax & carry) | C5: ='Investor Return'!$C$22 -> 0.15722408 | E5: Equity Investor MOIC (after carry) | G5: ='Investor Return'!$C$21 -> 1.43553
B6: Net profit to Equity Investors after carry (USD) | C6: ='Investor Return'!$C$20 -> 2926674.4 | E6: Total distributions to Equity Investors (USD) | G6: ='Investor Return'!$C$19 -> 9646474.6
B7: Capital drawn (USD) | C7: ='Investor Return'!$C$16 -> 6719800.2 | E7: Payback (model year) | G7: ='Investor Return'!$C$23 -> 4
B8: Authorized capital raise (USD) | C8: =Input!$C$37 -> 7000000 | E8: Fund life (years, through final sale) | G8: =Input!$C$57 -> 4
B9: 2. Equity Investor Kickers
B10: Kicker 1 — Lola & Ber Hospitality Brand Company equity interest | C10: =Input!$C$50 -> 0.03 | E10: Lola & Ber equity interest at current commitments | G10: =Input!$C$51 -> 0.009
B11: Kicker 2 — Dulcinea II pro-rata right of first refusal | C11: Pro rata | E11: Basis of pro-rata allocation | G11: Dulcinea I commitment
B12: Kicker 3 — Managing Partner structure of future funds | C12: Priority | E12: Applies to | G12: Future funds incl. Dulcinea chapters
B13: 3. Portfolio Value Creation
B14: All-in investment — active properties (USD) | C14: =SUMPRODUCT(Properties!$D$6:$D$15,Properties!$P$6:$P$15) -> 6571966 | E14: Portfolio IRR (deal-level, after gains tax) | G14: ='_IRR Engine'!$Q$17 -> 0.2081031
B15: Projected gross exit value (USD) | C15: =SUMPRODUCT(Properties!$D$6:$D$15,Properties!$W$6:$W$15) -> 11376911 | E15: Exit value ÷ all-in cost | G15: =IFERROR(C15/C14,0) -> 1.7311275
B16: Gross gain on property sales (USD) | C16: =SUMPRODUCT(Properties!$D$6:$D$15,Properties!$AC$6:$AC$15) -> 4372622.4 | E16: Average hold per property (years) | G16: =SUMPRODUCT(Properties!$D$6:$D$15,Properties!$V$6:$V$15)/SUM(Properties!$D$6:$D$15) -> 2.5
B17: Carry to Managing Partner (KIT Capital) (USD) | C17: =-'Investor Return'!$C$18 -> 731668.59 | E17: Active properties · backup properties | G17: =TEXT(SUM(Properties!$D$6:$D$15),"0")&" · "&TEXT(COUNTIF(Properties!$C$6:$C$19,"*Backup*"),"0") -> 5 · 4
B18: 4. STR Operations
B19: Stabilized STR revenue — active portfolio (USD/yr) | C19: =SUMPRODUCT(Properties!$D$6:$D$15,Properties!$Y$6:$Y$15) -> 307290.91 | E19: STR daily rates (USD/night) | G19: =TEXT(_xlfn.MINIFS(Input!$J$80:$J$89,Properties!$D$6:$D$15,1),"$#,##0")&"–"&TEXT(_xlfn.MAXIFS(Input!$J$80:$J$89,Properties!$D$6:$D$15,1),"$#,##0") -> $250–$340
B20: STR revenue over fund life (USD) | C20: =SUM('Income Statement'!$C$7:$L$7) -> 643426.99 | E20: Average booked occupancy | G20: =1-Input!$C$10 -> 0.6
B21: Rental contribution margin over fund life (USD) | C21: =SUM('Income Statement'!$C$112:$L$112) -> 506698.75 | E21: Rental CM % of STR revenue | G21: =IFERROR(C21/C20,0) -> 0.7875
B22: Fixed costs over fund life (USD) | C22: =SUM('Income Statement'!$C$145:$L$145) -> 652369.41 | E22: Minimum stay · price cap per 28 nights | G22: =TEXT(Input!$C$171,"0")&" nights · "&TEXT(Input!$C$170,"$#,##0") -> 28 nights · $9,500
B23: 5. Taxes & Macro
B24: Impuesto de Ganancia Ocasional — total (USD) | C24: =SUM('Income Statement'!$C$152:$L$152) -> 568608.75 | E24: Gains-tax rate (fixed, all sales) | G24: =Input!$C$26 -> 0.15
B25: Tax-basis indexation at US CPI (USD) | C25: =SUMPRODUCT(Properties!$D$6:$D$15,Properties!$AN$6:$AN$15)-SUMPRODUCT(Properties!$D$6:$D$15,Properties!$P$6:$P$15) -> 581897.37 | E25: US inflation — FRED CPI-U (YoY) | G25: =Input!$C$28 -> 0.0335
B26: STR revenue taxes over fund life (USD) | C26: =SUM('Income Statement'!$C$106:$L$106) -> 8042.8373 | E26: TRM (COP per USD, reference only) | G26: =Input!$C$5 -> 3090
B28: 6. Sensitivities, Portfolio & Cash-Flow Charts
B37: ="The "&TEXT(SUM(Properties!$D$6:$D$15),"0")&" active properties carry "&TEXT(SUMPRODUCT(Properties!$D$6:$D$15,Properties!$P$6:$P$15),"$#,##0")&" of all-in cost against "&TEXT(SUMPRODUCT(Properties!$D$6:$D$15,Properties!$W$6:$W$15),"$#,##0")&" of projected exit value — every one exits above cost, at a "&TEXT(SUMPRODUCT(Properties!$D$6:$D$15,Properties!$W$6:$W$15)/SUMPRODUCT(Properties!$D$6:$D$15,Properties!$P$6:$P$15)-1,"0%")&" uplift. "&TEXT(COUNTIF(Properties!$C$6:$C$19,"*Backup*"),"0")&" backup properties stay available as substitutes if a deal does not close." -> The 5 active properties carry $6,571,966 of all-in cost against $11,376,911 of projected exit value — every one exits above cost, at a 73% uplift. 4 backup properties stay available as substitutes if a deal does not close.
B46: {="Capital of "&TEXT(Input!$C$37,"$#,##0")&" is called only as acquisitions close, never up front. The first distribution lands in Year "&TEXT(MATCH(TRUE,INDEX('Investor Return'!$C$8:$L$8,0)>0,0),"0")&" as the first properties exit, cumulative investor cash turns positive in Year "&TEXT('Investor Return'!$C$23,"0")&", and the program returns "&TEXT('Investor Return'!$C$19,"$#,##0")&" on "&TEXT(Input!$C$37,"$#,##0")&" invested."} -> Capital of $7,000,000 is called only as acquisitions close, never up front. The first distribution lands in Year 3 as the first properties exit, cumulative investor cash turns positive in Year 4, and the program returns $9,646,475 on $7,000,000 invested.
B48: How Returns Are Generated
B49: ="Property sales of "&TEXT(SUM('Income Statement'!$C$18:$L$18),"$#,##0")&" and rental revenue of "&TEXT(SUM('Income Statement'!$C$7:$L$7),"$#,##0")&" over the life of the fund produce cumulative net income of "&TEXT(SUM('Income Statement'!$C$155:$L$155),"$#,##0;($#,##0)")&" after all Colombian taxes and operating costs." -> Property sales of $11,376,911 and rental revenue of $643,427 over the life of the fund produce cumulative net income of $3,658,343 after all Colombian taxes and operating costs.
B50: ="Equity Investors commit "&TEXT(Input!$C$37,"$#,##0")&", drawn only as acquisitions close, and receive distributions as each property exits — "&TEXT('Investor Return'!$C$19,"$#,##0")&" returned in total after the "&TEXT(Input!$C$46,"0%")&" Carry to the Managing Partner ("&TEXT(-'Investor Return'!$C$18,"$#,##0")&"), a "&TEXT('Investor Return'!$C$21,"0.00")&"x multiple and a "&TEXT('Investor Return'!$C$22,"0.0%")&" IRR, with capital fully recovered by Year "&TEXT('Investor Return'!$C$23,"0")&"." -> Equity Investors commit $7,000,000, drawn only as acquisitions close, and receive distributions as each property exits — $9,646,475 returned in total after the 20% Carry to the Managing Partner ($731,669), a 1.44x multiple and a 15.7% IRR, with capital fully recovered by Year 4.
B60: =_xlfn.LET(_xlpm.r,INDEX('Income Statement'!$C$155:$L$155,1,1):INDEX('Income Statement'!$C$155:$L$155,1,Input!$C$57),"Earnings arrive in the exit years, not evenly: Year "&TEXT(MATCH(MAX(_xlpm.r),_xlpm.r,0),"0")&" delivers "&TEXT(MAX(_xlpm.r),"$#,##0")&" and the fund totals "&TEXT(SUM(_xlpm.r),"$#,##0")&" of net income. Holding years carry STR rental contribution against fixed costs while capital is working in renovation and marketing rather than in rent.") -> Earnings arrive in the exit years, not evenly: Year 4 delivers $1,945,121 and the fund totals $3,658,343 of net income. Holding years carry STR rental contribution against fixed costs while capital is working in renovation and marketing rather than in rent.
B62: Discipline & Integrity
B63: ="Dulcinea carries no debt; properties are held at cost until sold. All operating services are provided by ServCo (an Ashoka unit) at benchmarked arm's-length fees, with executive costs allocated by time served. Every input lives on the Input tab; "&TEXT(COUNTA(Input!$C$99:$C$145),"0")&" automated integrity checks — foot and cross-foot on all three statements, engine reconciliations and reasonableness controls — currently read: "&Input!$C$146&"." -> Dulcinea carries no debt; properties are held at cost until sold. All operating services are provided by ServCo (an Ashoka unit) at benchmarked arm's-length fees, with executive costs allocated by time served. Every input lives on the Input tab; 43 automated integrity checks — foot and cross-foot on all three statements, engine reconciliations and reasonableness controls — currently read: ALL CHECKS PASS.
B73: {="No debt is drawn at any point and cash never goes negative in any year. The working capital reserve peaks at "&TEXT(MAX('Statement of Cash Flows'!$C$54:$L$54),"$#,##0")&" in Year "&TEXT(MATCH(MAX('Statement of Cash Flows'!$C$54:$L$54),'Statement of Cash Flows'!$C$54:$L$54,0),"0")&", runs down as the acquisition program completes, and the program closes at "&TEXT(INDEX('Statement of Cash Flows'!$C$54:$L$54,Input!$C$57),"$#,##0")&" at the final sale in Year "&TEXT(Input!$C$57,"0")&" — every purchase and works package funded from called capital rather than a facility."} -> No debt is drawn at any point and cash never goes negative in any year. The working capital reserve peaks at $24,326 in Year 1, runs down as the acquisition program completes, and the program closes at $0 at the final sale in Year 4 — every purchase and works package funded from called capital rather than a facility.
B74: Portfolio IRR (after gains tax) and Equity Investor IRR by entry discount — both anchored to the model at the base-case discount; other columns scale with the deal-level sensitivity on Portfolio Analysis
B75: Chart data (grouped — expand to view)
B76: Scenario | C76: ="Entry "&TEXT('Portfolio Analysis'!$C$178,"0%") -> Entry 20% | D76: ="Entry "&TEXT('Portfolio Analysis'!$C$179,"0%") -> Entry 25% | E76: ="Entry "&TEXT('Portfolio Analysis'!$C$180,"0%") -> Entry 30% | F76: ="Entry "&TEXT('Portfolio Analysis'!$C$181,"0%") -> Entry 35% | G76: ="Entry "&TEXT('Portfolio Analysis'!$C$182,"0%") -> Entry 40%
B77: Portfolio IRR | C77: ='Portfolio Analysis'!$E$178*'_IRR Engine'!$Q$17/'Portfolio Analysis'!$E$180 -> 0.15170478 | D77: ='Portfolio Analysis'!$E$179*'_IRR Engine'!$Q$17/'Portfolio Analysis'!$E$180 -> 0.17856188 | E77: ='Portfolio Analysis'!$E$180*'_IRR Engine'!$Q$17/'Portfolio Analysis'!$E$180 -> 0.2081031 | F77: ='Portfolio Analysis'!$E$181*'_IRR Engine'!$Q$17/'Portfolio Analysis'!$E$180 -> 0.2408201 | G77: ='Portfolio Analysis'!$E$182*'_IRR Engine'!$Q$17/'Portfolio Analysis'!$E$180 -> 0.27734213
B78: Equity Investor IRR | C78: ='Portfolio Analysis'!$E$178*'Investor Return'!$C$22/'Portfolio Analysis'!$E$180 -> 0.11461455 | D78: ='Portfolio Analysis'!$E$179*'Investor Return'!$C$22/'Portfolio Analysis'!$E$180 -> 0.13490537 | E78: ='Portfolio Analysis'!$E$180*'Investor Return'!$C$22/'Portfolio Analysis'!$E$180 -> 0.15722408 | F78: ='Portfolio Analysis'!$E$181*'Investor Return'!$C$22/'Portfolio Analysis'!$E$180 -> 0.18194211 | G78: ='Portfolio Analysis'!$E$182*'Investor Return'!$C$22/'Portfolio Analysis'!$E$180 -> 0.20953489
...

Sheet Input
B1: Dulcinea Portfolio Investment Model — Input
B2: Global model variables live on this tab. Per-deal inputs — selection flag, size, purchase & renovation prices, timing months — are the indigo cells on the Properties tab and feed the Portfolio Analysis analysis. Edit indigo-font cells only; formulas and linked values update automatically. USD presentation; COP inputs converted at the TRM below.
B4: General & FX | D4: Source / basis
B5: USD/COP exchange rate (TRM) | C5: 3090 | D5: Applied TRM per Dulcinea portfolio overview, 8/26/26
B6: COP depreciation vs USD (%/yr, projected) | C6: 0 | D6: Set to 0.0% on the post-election view — the peso strengthened from TRM ~3,757 to ~3,130 during 2026. Entry basis converts at the fixed TRM in C5. Raise this input to stress a weaker peso. Reference 11.
B7: Model start (Month 1 begins) | C7: 46296 | D7: First title transfers scheduled Sep 2026; model months run from Oct 2026
B8: Real rent growth (%/yr) — above inflation, excludes market appreciation | C8: 0.02
B9: Revenue & Exit
B10: Vacancy — active portfolio average, m²-weighted (derived from the per-property inputs) | C10: =SUMPRODUCT(Properties!$D$6:$D$15,Properties!$I$6:$I$15,$H$80:$H$89)/SUMPRODUCT(Properties!$D$6:$D$15,Properties!$I$6:$I$15) -> 0.4 | D10: ="Derived: m²-weighted average of the per-property vacancy inputs across the active portfolio, currently "&TEXT($C$10,"0%")&". Vacancy is set by unit size: the two mid-size El Poblado apartments are held at "&TEXT($H$81,"0%")&", inside the prime professionally-managed band of "&TEXT($C$168,"0%")&"–"&TEXT($D$168,"0%")&", while the "&TEXT(Properties!$I$6,"0")&" m² penthouse is held at "&TEXT($H$80,"0%")&" because the largest units are the slowest to let. The two El Retiro estates stay at "&TEXT($H$83,"0%")&" as no published series covers them. Market-wide Medellín runs "&TEXT($C$167,"0%")&"–"&TEXT($D$167,"0%")&" vacancy. References 14–16." -> Derived: m²-weighted average of the per-property vacancy inputs across the active portfolio, currently 40%. Vacancy is set by unit size: the two mid-size El Poblado apartments are held at 40%, inside the prime professionally-managed band of 35%–50%, while the 489 m² penthouse is held at 40% because the largest units are the slowest to let. The two El Retiro estates stay at 40% as no published series covers them. Market-wide Medellín runs 43%–57% vacancy. References 14–16.
B11: Rental ramp-up (months to stabilize) | C11: 1 | D11: Linear ramp after renovation completes
B12: Value uplift on all-in basis at exit (active portfolio) | C12: =SUMPRODUCT(Properties!$W$6:$W$15,Properties!$D$6:$D$15)/SUMPRODUCT(Properties!$P$6:$P$15,Properties!$D$6:$D$15)-1 -> 0.73112748
B13: Acquisition & Selling Costs
B14: Buyer closing costs — registration tax, registry rights & notary fees (Impuesto de Registro, Derechos de Registro y Derechos Notariales) (% of purchase price) | C14: 0.025 | D14: Notary share, registration tax and registry rights; market range 1.5%–3.5% of deed value
B15: Selling costs (% of sale price) | C15: 0.038 | D15: Broker commission (3%–5% market) plus seller notary share; 1% retención is a credit against capital gains tax, not an added cost
B17: Holding Costs — Global Rates
B18: Insurance — all-risk (%/yr of all-in basis) | C18: 0.0015 | D18: All-risk homeowner policies in Colombia typically run 0.1%–0.2% of value per year. Charged from rental start only — during the 6-month works the contractor carries construction all-risk cover.
B19: Maintenance reserve (%/yr of all-in basis) | C19: 0.005 | D19: Preventive upkeep on renovated luxury product
B20: Housekeeping & turnover (% of gross rent) — eliminated, now inside Property Management & Housekeeping (C31) | C20: 0 | D20: Set to zero 25 Sep 2026: cleaning and guest turnover are now covered by the combined 20% Property Management & Housekeeping fee.
B21: STR revenue taxes — Industry & Commerce Tax + Signage Tax + Tourism Promotion Levy (ICA + Avisos y Tableros + Contribución Parafiscal FONTUR) (revenue-weighted, derived) | C21: =IFERROR(SUMPRODUCT(Properties!$D$6:$D$15,Properties!$Y$6:$Y$15,Input!$U$80:$U$89)/SUMPRODUCT(Properties!$D$6:$D$15,Properties!$Y$6:$Y$15),0) -> 0.0125 | D21: Derived from the per-property tax columns O–U of the property table (per municipality). Used only for portfolio-level summaries; each property's P&L uses its own rate.
B22: Financial transactions tax (Gravamen a los Movimientos Financieros — GMF 4×1000, Art. 871 ET) (% of cash disbursements) | C22: 0.004 | D22: Financial transactions tax on bank debits
B24: Taxes
B25: Income tax on rental operation — capped at 15% per counsel (statutory Impuesto sobre la Renta, Art. 240 ET, is 35%) | C25: 0.15 | D25: Per counsel (25 Sep 2026): the fund's structure means it will never pay the 35% general rate; maximum effective tax rate on any income is 15%. Statutory reference: tarifa general 35% (Ley 2277 de 2022).
B26: Occasional gains tax on property sales — FIXED for all holds (Impuesto de Ganancia Ocasional, Arts. 300 y 313 ET) | C26: 0.15 | D26: Model convention: 15% applies to every sale regardless of hold length. Per counsel (25 Sep 2026) the fund's maximum tax rate on any income is 15%, so no sale or rental profit is taxed at the 35% statutory rate. See Glossary — Gains Tax Fixed at 15% (Model Exception).
B27: Value-added tax on lodging (IVA — servicio de hospedaje / vivienda turística, Art. 468 ET) — pass-through, not in P&L | C27: 0.19 | D27: STR rates are modeled NET of IVA (charged on top to the guest). Stays by non-resident foreign guests are exempt (Art. 481 lit. d ET; DUR 1625/2016 art. 1.3.1.11.1) if the unit is inscribed in the Registro Nacional de Turismo (RNT) and the passport/entry stamp is kept on file. Reference only — no formula uses this cell.
B28: US inflation rate for tax-cost adjustment (reajuste fiscal, Art. 70 ET — applied in USD) (%/yr) | C28: 0.0335 | D28: US CPI-U year over year to Aug 2026 from FRED series CPIAUCSL (334.131 vs 323.291 = +3.35%). Because all fund transactions are in USD, the all-in basis is indexed by US inflation (not the COP reajuste fiscal factor) for each year of hold, reducing the taxable gain. Blue input — update when FRED publishes new data.
B29: ServCo — Fees Charged to Dulcinea
B30: Asset management fee (% of basis owned, annual) | C30: 0.01
B31: Property management & housekeeping (% of gross rental revenue) | C31: 0.2 | D31: Single ServCo fee for running the rentals, including cleaning and guest turnover; replaces 15% management + 8% housekeeping.
B32: Service fee per owned property (USD / month) — consolidated into property management | C32: 0 | D32: Set to zero: concierge, housekeeping coordination and guest services are already covered by the single Property Management & Housekeeping fee (C31, 20% of gross rent), so a flat per-door charge would double-count the same service. A flat amount would also charge the $14/m² estates the same as the $28/m² penthouses. Reference 13 supports no flat per-door fee. Raise this input to reinstate one.
B34: Dulcinea Overhead
B35: Dulcinea legal, accounting & admin (USD / year) | C35: 30000
B36: Capital
B37: Total capital raise (USD) | C37: 7000000 | D37: Sized for acquisitions + works + closing + reserve; ServCo is compensated via fees within Dulcinea opex, not funded by the raise
B38: Total capital deployed (called capital plus shortfall absorbed, derived) | C38: ='Sources & Uses'!$C$8 -> 6806601.6 | D38: ="First "&TEXT($C$37/1000000,"$0.0")&"M of the raise is allocated to Dulcinea for property acquisition and improvements" -> First $7.0M of the raise is allocated to Dulcinea for property acquisition and improvements
B39: Working capital reserve (months of forward fund overheads held in cash) | C39: 3
B40: Unit price (USD per Unit, per Operating Agreement) | C40: 10000 | D40: Membership Units of Dulcinea Investments, LLC are issued at US$10,000 each
B41: Units issued to date | C41: 210 | D41: 210 Units issued under the Operating Agreement (3 Mar 2026) and First Amendment (2 Jul 2026)
B42: Capital committed to date (USD, derived) | C42: =C40*C41 -> 2100000 | D42: Capital already subscribed by existing Equity Investors — deployed to the two signed acquisitions (Aires de Campestre, Fontanar)
B43: Authorized capital ceiling (USD, Second Amendment) | C43: =C37 -> 7000000 | D43: Authorized capital raised from US$5.0M to US$7.0M — Second Amendment to the Operating Agreement (pending signature, Sep 2026)
B44: Supermajority Approval threshold (% of Equity Investors, excluding the Managing Partner) | C44: 0.8 | D44: Raised from 75% to 80% by the First Amendment; required for new acquisitions, dispositions, debt and capital increases
...

Sheet The Buy Box
B1: The Buy Box — Dulcinea I Acquisition Criteria
B2: What a property must look like to enter the fund · blue = Buy Box target · green = live link to the model
B4: Definition
B5: The Buy Box is our filter for what the fund buys. A property has to pass every criterion below — location, enjoyment, product, price, due diligence, remodel, operation, hold, deal size and return — before Dulcinea I commits capital. The short version: good homes in the right neighborhoods that Equity Investors will want to use, bought 20–30% below their renovated value, checked thoroughly so there are no expensive surprises, remodeled on schedule, and sold within the target hold.
B7: The Criteria
B8: Criterion | C8: Requirement | D8: Target
B9: 1 · Location | C9: El Poblado, Medellín (apartments and penthouses) and El Retiro, Antioquia (houses on land). Nothing outside these submarkets. | D9: El Poblado · El Retiro
B10: 2 · Enjoyment for Equity Investors | C10: A place Equity Investors would actually want to spend time in. Enjoying the homes is one of the core objectives of Dulcinea, alongside the return. | D10: Homes Equity Investors want to use
B11: 3 · Product | C11: Distinctive, larger homes with clear room to add value and appeal to international buyers and guests. | D11: 300–600 m²
B12: 4 · Entry price | C12: At least 20–30% below the home's renovated comparable value. This discount is the main source of return. | D12: 20–30% below improved value
B13: 5 · Transformation | C13: A full remodel including all furniture, fixtures and equipment, delivered turnkey on a defined schedule and budget. | D13: About 6 months of works
B14: 6 · Deep due diligence | C14: A thorough technical, legal and regulatory review before purchase — structure, roof, waterproofing, plumbing, electrical, humidity, site and soil, permits and licensing, title (tradición y libertad), liens, HOA rules for short-term rentals and pending assessments. The goal is to catch problems that would raise remodel costs or cause delays and push the property outside the other criteria. | D14: Full technical, legal & title review · works budget with contingency before commitment
B15: 7 · Operation | C15: Ready to rent as a fully equipped furnished home with a four-week minimum stay, priced in US dollars within the per-stay cap. | D15: $300–$1,000 per night · $9,500 cap per 28 nights
B16: 8 · Hold & exit | C16: Sell within about two to three years of purchase, once remodeled and seasoned as a rental. | D16: 24–36 months
B17: 9 · Deal size | C17: All-in cost per property sized to the fund so no single home dominates the portfolio. | D17: $750K–$2M all-in
B18: 10 · Minimum return | C18: Minimum deal-level IRR, after gains tax, each property must be underwritten to (per the 23 Sep 2026 corporate update). | D18: 20% IRR minimum
B20: Portfolio Check — Active Properties Against the Buy Box
B21: Property | C21: Location | D21: Size (m²) | E21: Entry discount | F21: Works (months) | G21: Daily rate (USD) | H21: Hold (months) | I21: All-in basis (USD) | J21: Inside the Buy Box?
B22: =Properties!$E$6 -> Aires de Campestre Apto 801 (Penthouse) | C22: =Properties!$F$6 -> El Poblado, Medellín | D22: =Properties!$I$6 -> 489 | E22: =Input!$I$80 -> 0.3 | F22: =Input!$M$80 -> 6 | G22: =Input!$J$80 -> 270 | H22: =Properties!$S$6 -> 28 | I22: =Properties!$P$6 -> 1168770.2 | J22: =IF(AND(OR(ISNUMBER(SEARCH("Poblado",C22)),ISNUMBER(SEARCH("Retiro",C22))),E22>=$C$35,H22<=$C$36,I22>0),"Yes","Review") -> Yes
B23: =Properties!$E$7 -> Fontanar Apto 201 (Penthouse) | C23: =Properties!$F$7 -> El Poblado, Medellín | D23: =Properties!$I$7 -> 389 | E23: =Input!$I$81 -> 0.3 | F23: =Input!$M$81 -> 6 | G23: =Input!$J$81 -> 270 | H23: =Properties!$S$7 -> 30 | I23: =Properties!$P$7 -> 1290857.6 | J23: =IF(AND(OR(ISNUMBER(SEARCH("Poblado",C23)),ISNUMBER(SEARCH("Retiro",C23))),E23>=$C$35,H23<=$C$36,I23>0),"Yes","Review") -> Yes
B24: =Properties!$E$8 -> San Lucas Apto 101 | C24: =Properties!$F$8 -> El Poblado, Medellín | D24: =Properties!$I$8 -> 325 | E24: =Input!$I$82 -> 0.3 | F24: =Input!$M$82 -> 6 | G24: =Input!$J$82 -> 250 | H24: =Properties!$S$8 -> 25 | I24: =Properties!$P$8 -> 747370.55 | J24: =IF(AND(OR(ISNUMBER(SEARCH("Poblado",C24)),ISNUMBER(SEARCH("Retiro",C24))),E24>=$C$35,H24<=$C$36,I24>0),"Yes","Review") -> Yes
B25: =Properties!$E$9 -> Casa Montana Lote 2 (Samuel Gaviria House) | C25: =Properties!$F$9 -> El Retiro, Antioquia | D25: =Properties!$I$9 -> 591 | E25: =Input!$I$83 -> 0.3 | F25: =Input!$M$83 -> 6 | G25: =Input!$J$83 -> 340 | H25: =Properties!$S$9 -> 35 | I25: =Properties!$P$9 -> 1714482.2 | J25: =IF(AND(OR(ISNUMBER(SEARCH("Poblado",C25)),ISNUMBER(SEARCH("Retiro",C25))),E25>=$C$35,H25<=$C$36,I25>0),"Yes","Review") -> Yes
B26: =Properties!$E$10 -> Casa Monte Sereno | C26: =Properties!$F$10 -> El Retiro, Antioquia | D26: =Properties!$I$10 -> 420 | E26: =Input!$I$84 -> 0.3 | F26: =Input!$M$84 -> 6 | G26: =Input!$J$84 -> 270 | H26: =Properties!$S$10 -> 32 | I26: =Properties!$P$10 -> 1650485.4 | J26: =IF(AND(OR(ISNUMBER(SEARCH("Poblado",C26)),ISNUMBER(SEARCH("Retiro",C26))),E26>=$C$35,H26<=$C$36,I26>0),"Yes","Review") -> Yes
B27: Test applied: target submarket · entry discount at or above the minimum · hold at or below the maximum (thresholds below).
B28: Portfolio deal-level IRR (after gains tax) vs 20% minimum | C28: ='_IRR Engine'!$Q$17 -> 0.2081031 | D28: =IF(C28>=$C$37,"Meets minimum","Below minimum") -> Meets minimum
B29: Sourcing Funnel (per the 23 Sep 2026 corporate update)
B30: Properties seen | C30: 60+ | D30: Visited and screened by the team
B31: Catalogued inside the Buy Box | C31: 14 | D31: Met the criteria and were documented
B32: Selected for Dulcinea I | C32: =SUM(Properties!$D$6:$D$15) -> 5 | D32: Active properties in the fund
B34: Buy Box Test Thresholds
B35: Minimum entry discount | C35: 0.2 | D35: Lower bound of the 20–30% entry-price criterion
B36: Maximum hold (months) | C36: 36 | D36: Upper bound of the two-to-three-year hold criterion
B37: Minimum deal-level IRR (after gains tax) | C37: 0.2 | D37: Buy Box minimum return — portfolio deal-level IRR is tested against it

Sheet Income Statement
B1: ="Dulcinea — Income Statement, Years 1–"&TEXT(Input!$C$57,"0")&" (USD) · through final sale" -> Dulcinea — Income Statement, Years 1–4 (USD) · through final sale
B2: Contribution-margin format. See Notes to Financials.
B4: Model year | C4: =COLUMN()-2 -> 1 | D4: =COLUMN()-2 -> 2 | E4: =COLUMN()-2 -> 3 | F4: =COLUMN()-2 -> 4 | G4: =COLUMN()-2 -> 5 | H4: =COLUMN()-2 -> 6 | I4: =COLUMN()-2 -> 7 | J4: =COLUMN()-2 -> 8 | ... L4: =COLUMN()-2 -> 10
B5: Period | C5: =TEXT(EDATE(Input!$C$7,(C4-1)*12),"mmm-yy")&" – "&TEXT(EDATE(Input!$C$7,C4*12-1),"mmm-yy") -> Oct-26 – Sep-27 | D5: =TEXT(EDATE(Input!$C$7,(D4-1)*12),"mmm-yy")&" – "&TEXT(EDATE(Input!$C$7,D4*12-1),"mmm-yy") -> Oct-27 – Sep-28 | E5: =TEXT(EDATE(Input!$C$7,(E4-1)*12),"mmm-yy")&" – "&TEXT(EDATE(Input!$C$7,E4*12-1),"mmm-yy") -> Oct-28 – Sep-29 | F5: =TEXT(EDATE(Input!$C$7,(F4-1)*12),"mmm-yy")&" – "&TEXT(EDATE(Input!$C$7,F4*12-1),"mmm-yy") -> Oct-29 – Sep-30 | G5: =TEXT(EDATE(Input!$C$7,(G4-1)*12),"mmm-yy")&" – "&TEXT(EDATE(Input!$C$7,G4*12-1),"mmm-yy") -> Oct-30 – Sep-31 | H5: =TEXT(EDATE(Input!$C$7,(H4-1)*12),"mmm-yy")&" – "&TEXT(EDATE(Input!$C$7,H4*12-1),"mmm-yy") -> Oct-31 – Sep-32 | I5: =TEXT(EDATE(Input!$C$7,(I4-1)*12),"mmm-yy")&" – "&TEXT(EDATE(Input!$C$7,I4*12-1),"mmm-yy") -> Oct-32 – Sep-33 | J5: =TEXT(EDATE(Input!$C$7,(J4-1)*12),"mmm-yy")&" – "&TEXT(EDATE(Input!$C$7,J4*12-1),"mmm-yy") -> Oct-33 – Sep-34 | ... L5: =TEXT(EDATE(Input!$C$7,(L4-1)*12),"mmm-yy")&" – "&TEXT(EDATE(Input!$C$7,L4*12-1),"mmm-yy") -> Oct-35 – Sep-36
B6: Revenue
B7: STR rental revenue | C7: =SUMIF('_Month Engine'!$C$5:$DR$5,C$4,'_Month Engine'!$C$44:$DR$44) -> 84225.675 | D7: =SUMIF('_Month Engine'!$C$5:$DR$5,D$4,'_Month Engine'!$C$44:$DR$44) -> 308211.84 | E7: =SUMIF('_Month Engine'!$C$5:$DR$5,E$4,'_Month Engine'!$C$44:$DR$44) -> 210510.48 | F7: =SUMIF('_Month Engine'!$C$5:$DR$5,F$4,'_Month Engine'!$C$44:$DR$44) -> 40478.989 | G7: =SUMIF('_Month Engine'!$C$5:$DR$5,G$4,'_Month Engine'!$C$44:$DR$44) -> 0 | H7: =SUMIF('_Month Engine'!$C$5:$DR$5,H$4,'_Month Engine'!$C$44:$DR$44) -> 0 | I7: =SUMIF('_Month Engine'!$C$5:$DR$5,I$4,'_Month Engine'!$C$44:$DR$44) -> 0 | J7: =SUMIF('_Month Engine'!$C$5:$DR$5,J$4,'_Month Engine'!$C$44:$DR$44) -> 0 | ... L7: =SUMIF('_Month Engine'!$C$5:$DR$5,L$4,'_Month Engine'!$C$44:$DR$44) -> 0
B8: =IF(Properties!$D$6=0,"",Properties!E6) -> Aires de Campestre Apto 801 (Penthouse) | C8: ='Property Detail'!C8 -> 25517.025 | D8: ='Property Detail'!D8 -> 60811.625 | E8: ='Property Detail'!E8 -> 26681.485 | F8: ='Property Detail'!F8 -> 0 | G8: ='Property Detail'!G8 -> 0 | H8: ='Property Detail'!H8 -> 0 | I8: ='Property Detail'!I8 -> 0 | J8: ='Property Detail'!J8 -> 0 | ... L8: ='Property Detail'!L8 -> 0
B9: =IF(Properties!$D$7=0,"",Properties!E7) -> Fontanar Apto 201 (Penthouse) | C9: ='Property Detail'!C24 -> 29441.475 | D9: ='Property Detail'!D24 -> 60811.625 | E9: ='Property Detail'!E24 -> 31396.947 | F9: ='Property Detail'!F24 -> 0 | G9: ='Property Detail'!G24 -> 0 | H9: ='Property Detail'!H24 -> 0 | I9: ='Property Detail'!I24 -> 0 | J9: ='Property Detail'!J24 -> 0 | ... L9: ='Property Detail'!L24 -> 0
B10: =IF(Properties!$D$8=0,"",Properties!E8) -> San Lucas Apto 101 | C10: ='Property Detail'!C40 -> 20069.625 | D10: ='Property Detail'!D40 -> 56307.06 | E10: ='Property Detail'!E40 -> 14215.505 | F10: ='Property Detail'!F40 -> 0 | G10: ='Property Detail'!G40 -> 0 | H10: ='Property Detail'!H40 -> 0 | I10: ='Property Detail'!I40 -> 0 | J10: ='Property Detail'!J40 -> 0 | ... L10: ='Property Detail'!L40 -> 0
B11: =IF(Properties!$D$9=0,"",Properties!E9) -> Casa Montana Lote 2 (Samuel Gaviria House) | C11: ='Property Detail'!C56 -> 0 | D11: ='Property Detail'!D56 -> 69124.14 | E11: ='Property Detail'!E56 -> 75836.01 | F11: ='Property Detail'!F56 -> 40478.989 | G11: ='Property Detail'!G56 -> 0 | H11: ='Property Detail'!H56 -> 0 | I11: ='Property Detail'!I56 -> 0 | J11: ='Property Detail'!J56 -> 0 | ... L11: ='Property Detail'!L56 -> 0
B12: =IF(Properties!$D$10=0,"",Properties!E10) -> Casa Monte Sereno | C12: ='Property Detail'!C72 -> 9197.55 | D12: ='Property Detail'!D72 -> 61157.389 | E12: ='Property Detail'!E72 -> 62380.537 | F12: ='Property Detail'!F72 -> 0 | G12: ='Property Detail'!G72 -> 0 | H12: ='Property Detail'!H72 -> 0 | I12: ='Property Detail'!I72 -> 0 | J12: ='Property Detail'!J72 -> 0 | ... L12: ='Property Detail'!L72 -> 0
B13: =IF(Properties!$D$11=0,"",Properties!E11) | C13: ='Property Detail'!C88 -> 0 | D13: ='Property Detail'!D88 -> 0 | E13: ='Property Detail'!E88 -> 0 | F13: ='Property Detail'!F88 -> 0 | G13: ='Property Detail'!G88 -> 0 | H13: ='Property Detail'!H88 -> 0 | I13: ='Property Detail'!I88 -> 0 | J13: ='Property Detail'!J88 -> 0 | ... L13: ='Property Detail'!L88 -> 0
B14: =IF(Properties!$D$12=0,"",Properties!E12) | C14: ='Property Detail'!C104 -> 0 | D14: ='Property Detail'!D104 -> 0 | E14: ='Property Detail'!E104 -> 0 | F14: ='Property Detail'!F104 -> 0 | G14: ='Property Detail'!G104 -> 0 | H14: ='Property Detail'!H104 -> 0 | I14: ='Property Detail'!I104 -> 0 | J14: ='Property Detail'!J104 -> 0 | ... L14: ='Property Detail'!L104 -> 0
B15: =IF(Properties!$D$13=0,"",Properties!E13) | C15: ='Property Detail'!C120 -> 0 | D15: ='Property Detail'!D120 -> 0 | E15: ='Property Detail'!E120 -> 0 | F15: ='Property Detail'!F120 -> 0 | G15: ='Property Detail'!G120 -> 0 | H15: ='Property Detail'!H120 -> 0 | I15: ='Property Detail'!I120 -> 0 | J15: ='Property Detail'!J120 -> 0 | ... L15: ='Property Detail'!L120 -> 0
B16: =IF(Properties!$D$14=0,"",Properties!E14) | C16: ='Property Detail'!C136 -> 0 | D16: ='Property Detail'!D136 -> 0 | E16: ='Property Detail'!E136 -> 0 | F16: ='Property Detail'!F136 -> 0 | G16: ='Property Detail'!G136 -> 0 | H16: ='Property Detail'!H136 -> 0 | I16: ='Property Detail'!I136 -> 0 | J16: ='Property Detail'!J136 -> 0 | ... L16: ='Property Detail'!L136 -> 0
B17: =IF(Properties!$D$15=0,"",Properties!E15) | C17: ='Property Detail'!C152 -> 0 | D17: ='Property Detail'!D152 -> 0 | E17: ='Property Detail'!E152 -> 0 | F17: ='Property Detail'!F152 -> 0 | G17: ='Property Detail'!G152 -> 0 | H17: ='Property Detail'!H152 -> 0 | I17: ='Property Detail'!I152 -> 0 | J17: ='Property Detail'!J152 -> 0 | ... L17: ='Property Detail'!L152 -> 0
B18: Property sales (gross) | C18: =SUMIF('_Month Engine'!$C$5:$DR$5,C$4,'_Month Engine'!$C$71:$DR$71) -> 0 | D18: =SUMIF('_Month Engine'!$C$5:$DR$5,D$4,'_Month Engine'!$C$71:$DR$71) -> 0 | E18: =SUMIF('_Month Engine'!$C$5:$DR$5,E$4,'_Month Engine'!$C$71:$DR$71) -> 5546509.2 | F18: =SUMIF('_Month Engine'!$C$5:$DR$5,F$4,'_Month Engine'!$C$71:$DR$71) -> 5830401.8 | G18: =SUMIF('_Month Engine'!$C$5:$DR$5,G$4,'_Month Engine'!$C$71:$DR$71) -> 0 | H18: =SUMIF('_Month Engine'!$C$5:$DR$5,H$4,'_Month Engine'!$C$71:$DR$71) -> 0 | I18: =SUMIF('_Month Engine'!$C$5:$DR$5,I$4,'_Month Engine'!$C$71:$DR$71) -> 0 | J18: =SUMIF('_Month Engine'!$C$5:$DR$5,J$4,'_Month Engine'!$C$71:$DR$71) -> 0 | ... L18: =SUMIF('_Month Engine'!$C$5:$DR$5,L$4,'_Month Engine'!$C$71:$DR$71) -> 0
B19: =IF(Properties!$D$6=0,"",Properties!E6) -> Aires de Campestre Apto 801 (Penthouse) | C19: =IF(ROUNDUP(Properties!$U6/'_IRR Engine'!$Q$7,0)=C$4,Properties!$D6*Properties!$W6,0) -> 0 | D19: =IF(ROUNDUP(Properties!$U6/'_IRR Engine'!$Q$7,0)=D$4,Properties!$D6*Properties!$W6,0) -> 0 | E19: =IF(ROUNDUP(Properties!$U6/'_IRR Engine'!$Q$7,0)=E$4,Properties!$D6*Properties!$W6,0) -> 2019763.4 | F19: =IF(ROUNDUP(Properties!$U6/'_IRR Engine'!$Q$7,0)=F$4,Properties!$D6*Properties!$W6,0) -> 0 | G19: =IF(ROUNDUP(Properties!$U6/'_IRR Engine'!$Q$7,0)=G$4,Properties!$D6*Properties!$W6,0) -> 0 | H19: =IF(ROUNDUP(Properties!$U6/'_IRR Engine'!$Q$7,0)=H$4,Properties!$D6*Properties!$W6,0) -> 0 | I19: =IF(ROUNDUP(Properties!$U6/'_IRR Engine'!$Q$7,0)=I$4,Properties!$D6*Properties!$W6,0) -> 0 | J19: =IF(ROUNDUP(Properties!$U6/'_IRR Engine'!$Q$7,0)=J$4,Properties!$D6*Properties!$W6,0) -> 0 | ... L19: =IF(ROUNDUP(Properties!$U6/'_IRR Engine'!$Q$7,0)=L$4,Properties!$D6*Properties!$W6,0) -> 0
B20: =IF(Properties!$D$7=0,"",Properties!E7) -> Fontanar Apto 201 (Penthouse) | C20: =IF(ROUNDUP(Properties!$U7/'_IRR Engine'!$Q$7,0)=C$4,Properties!$D7*Properties!$W7,0) -> 0 | D20: =IF(ROUNDUP(Properties!$U7/'_IRR Engine'!$Q$7,0)=D$4,Properties!$D7*Properties!$W7,0) -> 0 | E20: =IF(ROUNDUP(Properties!$U7/'_IRR Engine'!$Q$7,0)=E$4,Properties!$D7*Properties!$W7,0) -> 2261281.6 | F20: =IF(ROUNDUP(Properties!$U7/'_IRR Engine'!$Q$7,0)=F$4,Properties!$D7*Properties!$W7,0) -> 0 | G20: =IF(ROUNDUP(Properties!$U7/'_IRR Engine'!$Q$7,0)=G$4,Properties!$D7*Properties!$W7,0) -> 0 | H20: =IF(ROUNDUP(Properties!$U7/'_IRR Engine'!$Q$7,0)=H$4,Properties!$D7*Properties!$W7,0) -> 0 | I20: =IF(ROUNDUP(Properties!$U7/'_IRR Engine'!$Q$7,0)=I$4,Properties!$D7*Properties!$W7,0) -> 0 | J20: =IF(ROUNDUP(Properties!$U7/'_IRR Engine'!$Q$7,0)=J$4,Properties!$D7*Properties!$W7,0) -> 0 | ... L20: =IF(ROUNDUP(Properties!$U7/'_IRR Engine'!$Q$7,0)=L$4,Properties!$D7*Properties!$W7,0) -> 0
B21: =IF(Properties!$D$8=0,"",Properties!E8) -> San Lucas Apto 101 | C21: =IF(ROUNDUP(Properties!$U8/'_IRR Engine'!$Q$7,0)=C$4,Properties!$D8*Properties!$W8,0) -> 0 | D21: =IF(ROUNDUP(Properties!$U8/'_IRR Engine'!$Q$7,0)=D$4,Properties!$D8*Properties!$W8,0) -> 0 | E21: =IF(ROUNDUP(Properties!$U8/'_IRR Engine'!$Q$7,0)=E$4,Properties!$D8*Properties!$W8,0) -> 1265464.3 | F21: =IF(ROUNDUP(Properties!$U8/'_IRR Engine'!$Q$7,0)=F$4,Properties!$D8*Properties!$W8,0) -> 0 | G21: =IF(ROUNDUP(Properties!$U8/'_IRR Engine'!$Q$7,0)=G$4,Properties!$D8*Properties!$W8,0) -> 0 | H21: =IF(ROUNDUP(Properties!$U8/'_IRR Engine'!$Q$7,0)=H$4,Properties!$D8*Properties!$W8,0) -> 0 | I21: =IF(ROUNDUP(Properties!$U8/'_IRR Engine'!$Q$7,0)=I$4,Properties!$D8*Properties!$W8,0) -> 0 | J21: =IF(ROUNDUP(Properties!$U8/'_IRR Engine'!$Q$7,0)=J$4,Properties!$D8*Properties!$W8,0) -> 0 | ... L21: =IF(ROUNDUP(Properties!$U8/'_IRR Engine'!$Q$7,0)=L$4,Properties!$D8*Properties!$W8,0) -> 0
B22: =IF(Properties!$D$9=0,"",Properties!E9) -> Casa Montana Lote 2 (Samuel Gaviria House) | C22: =IF(ROUNDUP(Properties!$U9/'_IRR Engine'!$Q$7,0)=C$4,Properties!$D9*Properties!$W9,0) -> 0 | D22: =IF(ROUNDUP(Properties!$U9/'_IRR Engine'!$Q$7,0)=D$4,Properties!$D9*Properties!$W9,0) -> 0 | E22: =IF(ROUNDUP(Properties!$U9/'_IRR Engine'!$Q$7,0)=E$4,Properties!$D9*Properties!$W9,0) -> 0 | F22: =IF(ROUNDUP(Properties!$U9/'_IRR Engine'!$Q$7,0)=F$4,Properties!$D9*Properties!$W9,0) -> 2995795.2 | G22: =IF(ROUNDUP(Properties!$U9/'_IRR Engine'!$Q$7,0)=G$4,Properties!$D9*Properties!$W9,0) -> 0 | H22: =IF(ROUNDUP(Properties!$U9/'_IRR Engine'!$Q$7,0)=H$4,Properties!$D9*Properties!$W9,0) -> 0 | I22: =IF(ROUNDUP(Properties!$U9/'_IRR Engine'!$Q$7,0)=I$4,Properties!$D9*Properties!$W9,0) -> 0 | J22: =IF(ROUNDUP(Properties!$U9/'_IRR Engine'!$Q$7,0)=J$4,Properties!$D9*Properties!$W9,0) -> 0 | ... L22: =IF(ROUNDUP(Properties!$U9/'_IRR Engine'!$Q$7,0)=L$4,Properties!$D9*Properties!$W9,0) -> 0
B23: =IF(Properties!$D$10=0,"",Properties!E10) -> Casa Monte Sereno | C23: =IF(ROUNDUP(Properties!$U10/'_IRR Engine'!$Q$7,0)=C$4,Properties!$D10*Properties!$W10,0) -> 0 | D23: =IF(ROUNDUP(Properties!$U10/'_IRR Engine'!$Q$7,0)=D$4,Properties!$D10*Properties!$W10,0) -> 0 | E23: =IF(ROUNDUP(Properties!$U10/'_IRR Engine'!$Q$7,0)=E$4,Properties!$D10*Properties!$W10,0) -> 0 | F23: =IF(ROUNDUP(Properties!$U10/'_IRR Engine'!$Q$7,0)=F$4,Properties!$D10*Properties!$W10,0) -> 2834606.6 | G23: =IF(ROUNDUP(Properties!$U10/'_IRR Engine'!$Q$7,0)=G$4,Properties!$D10*Properties!$W10,0) -> 0 | H23: =IF(ROUNDUP(Properties!$U10/'_IRR Engine'!$Q$7,0)=H$4,Properties!$D10*Properties!$W10,0) -> 0 | I23: =IF(ROUNDUP(Properties!$U10/'_IRR Engine'!$Q$7,0)=I$4,Properties!$D10*Properties!$W10,0) -> 0 | J23: =IF(ROUNDUP(Properties!$U10/'_IRR Engine'!$Q$7,0)=J$4,Properties!$D10*Properties!$W10,0) -> 0 | ... L23: =IF(ROUNDUP(Properties!$U10/'_IRR Engine'!$Q$7,0)=L$4,Properties!$D10*Properties!$W10,0) -> 0
B24: =IF(Properties!$D$11=0,"",Properties!E11) | C24: =IF(ROUNDUP(Properties!$U11/'_IRR Engine'!$Q$7,0)=C$4,Properties!$D11*Properties!$W11,0) -> 0 | D24: =IF(ROUNDUP(Properties!$U11/'_IRR Engine'!$Q$7,0)=D$4,Properties!$D11*Properties!$W11,0) -> 0 | E24: =IF(ROUNDUP(Properties!$U11/'_IRR Engine'!$Q$7,0)=E$4,Properties!$D11*Properties!$W11,0) -> 0 | F24: =IF(ROUNDUP(Properties!$U11/'_IRR Engine'!$Q$7,0)=F$4,Properties!$D11*Properties!$W11,0) -> 0 | G24: =IF(ROUNDUP(Properties!$U11/'_IRR Engine'!$Q$7,0)=G$4,Properties!$D11*Properties!$W11,0) -> 0 | H24: =IF(ROUNDUP(Properties!$U11/'_IRR Engine'!$Q$7,0)=H$4,Properties!$D11*Properties!$W11,0) -> 0 | I24: =IF(ROUNDUP(Properties!$U11/'_IRR Engine'!$Q$7,0)=I$4,Properties!$D11*Properties!$W11,0) -> 0 | J24: =IF(ROUNDUP(Properties!$U11/'_IRR Engine'!$Q$7,0)=J$4,Properties!$D11*Properties!$W11,0) -> 0 | ... L24: =IF(ROUNDUP(Properties!$U11/'_IRR Engine'!$Q$7,0)=L$4,Properties!$D11*Properties!$W11,0) -> 0
B25: =IF(Properties!$D$12=0,"",Properties!E12) | C25: =IF(ROUNDUP(Properties!$U12/'_IRR Engine'!$Q$7,0)=C$4,Properties!$D12*Properties!$W12,0) -> 0 | D25: =IF(ROUNDUP(Properties!$U12/'_IRR Engine'!$Q$7,0)=D$4,Properties!$D12*Properties!$W12,0) -> 0 | E25: =IF(ROUNDUP(Properties!$U12/'_IRR Engine'!$Q$7,0)=E$4,Properties!$D12*Properties!$W12,0) -> 0 | F25: =IF(ROUNDUP(Properties!$U12/'_IRR Engine'!$Q$7,0)=F$4,Properties!$D12*Properties!$W12,0) -> 0 | G25: =IF(ROUNDUP(Properties!$U12/'_IRR Engine'!$Q$7,0)=G$4,Properties!$D12*Properties!$W12,0) -> 0 | H25: =IF(ROUNDUP(Properties!$U12/'_IRR Engine'!$Q$7,0)=H$4,Properties!$D12*Properties!$W12,0) -> 0 | I25: =IF(ROUNDUP(Properties!$U12/'_IRR Engine'!$Q$7,0)=I$4,Properties!$D12*Properties!$W12,0) -> 0 | J25: =IF(ROUNDUP(Properties!$U12/'_IRR Engine'!$Q$7,0)=J$4,Properties!$D12*Properties!$W12,0) -> 0 | ... L25: =IF(ROUNDUP(Properties!$U12/'_IRR Engine'!$Q$7,0)=L$4,Properties!$D12*Properties!$W12,0) -> 0
B26: =IF(Properties!$D$13=0,"",Properties!E13) | C26: =IF(ROUNDUP(Properties!$U13/'_IRR Engine'!$Q$7,0)=C$4,Properties!$D13*Properties!$W13,0) -> 0 | D26: =IF(ROUNDUP(Properties!$U13/'_IRR Engine'!$Q$7,0)=D$4,Properties!$D13*Properties!$W13,0) -> 0 | E26: =IF(ROUNDUP(Properties!$U13/'_IRR Engine'!$Q$7,0)=E$4,Properties!$D13*Properties!$W13,0) -> 0 | F26: =IF(ROUNDUP(Properties!$U13/'_IRR Engine'!$Q$7,0)=F$4,Properties!$D13*Properties!$W13,0) -> 0 | G26: =IF(ROUNDUP(Properties!$U13/'_IRR Engine'!$Q$7,0)=G$4,Properties!$D13*Properties!$W13,0) -> 0 | H26: =IF(ROUNDUP(Properties!$U13/'_IRR Engine'!$Q$7,0)=H$4,Properties!$D13*Properties!$W13,0) -> 0 | I26: =IF(ROUNDUP(Properties!$U13/'_IRR Engine'!$Q$7,0)=I$4,Properties!$D13*Properties!$W13,0) -> 0 | J26: =IF(ROUNDUP(Properties!$U13/'_IRR Engine'!$Q$7,0)=J$4,Properties!$D13*Properties!$W13,0) -> 0 | ... L26: =IF(ROUNDUP(Properties!$U13/'_IRR Engine'!$Q$7,0)=L$4,Properties!$D13*Properties!$W13,0) -> 0
B27: =IF(Properties!$D$14=0,"",Properties!E14) | C27: =IF(ROUNDUP(Properties!$U14/'_IRR Engine'!$Q$7,0)=C$4,Properties!$D14*Properties!$W14,0) -> 0 | D27: =IF(ROUNDUP(Properties!$U14/'_IRR Engine'!$Q$7,0)=D$4,Properties!$D14*Properties!$W14,0) -> 0 | E27: =IF(ROUNDUP(Properties!$U14/'_IRR Engine'!$Q$7,0)=E$4,Properties!$D14*Properties!$W14,0) -> 0 | F27: =IF(ROUNDUP(Properties!$U14/'_IRR Engine'!$Q$7,0)=F$4,Properties!$D14*Properties!$W14,0) -> 0 | G27: =IF(ROUNDUP(Properties!$U14/'_IRR Engine'!$Q$7,0)=G$4,Properties!$D14*Properties!$W14,0) -> 0 | H27: =IF(ROUNDUP(Properties!$U14/'_IRR Engine'!$Q$7,0)=H$4,Properties!$D14*Properties!$W14,0) -> 0 | I27: =IF(ROUNDUP(Properties!$U14/'_IRR Engine'!$Q$7,0)=I$4,Properties!$D14*Properties!$W14,0) -> 0 | J27: =IF(ROUNDUP(Properties!$U14/'_IRR Engine'!$Q$7,0)=J$4,Properties!$D14*Properties!$W14,0) -> 0 | ... L27: =IF(ROUNDUP(Properties!$U14/'_IRR Engine'!$Q$7,0)=L$4,Properties!$D14*Properties!$W14,0) -> 0
B28: =IF(Properties!$D$15=0,"",Properties!E15) | C28: =IF(ROUNDUP(Properties!$U15/'_IRR Engine'!$Q$7,0)=C$4,Properties!$D15*Properties!$W15,0) -> 0 | D28: =IF(ROUNDUP(Properties!$U15/'_IRR Engine'!$Q$7,0)=D$4,Properties!$D15*Properties!$W15,0) -> 0 | E28: =IF(ROUNDUP(Properties!$U15/'_IRR Engine'!$Q$7,0)=E$4,Properties!$D15*Properties!$W15,0) -> 0 | F28: =IF(ROUNDUP(Properties!$U15/'_IRR Engine'!$Q$7,0)=F$4,Properties!$D15*Properties!$W15,0) -> 0 | G28: =IF(ROUNDUP(Properties!$U15/'_IRR Engine'!$Q$7,0)=G$4,Properties!$D15*Properties!$W15,0) -> 0 | H28: =IF(ROUNDUP(Properties!$U15/'_IRR Engine'!$Q$7,0)=H$4,Properties!$D15*Properties!$W15,0) -> 0 | I28: =IF(ROUNDUP(Properties!$U15/'_IRR Engine'!$Q$7,0)=I$4,Properties!$D15*Properties!$W15,0) -> 0 | J28: =IF(ROUNDUP(Properties!$U15/'_IRR Engine'!$Q$7,0)=J$4,Properties!$D15*Properties!$W15,0) -> 0 | ... L28: =IF(ROUNDUP(Properties!$U15/'_IRR Engine'!$Q$7,0)=L$4,Properties!$D15*Properties!$W15,0) -> 0
B29: Total revenue | C29: =C7+C18 -> 84225.675 | D29: =D7+D18 -> 308211.84 | E29: =E7+E18 -> 5757019.7 | F29: =F7+F18 -> 5870880.8 | G29: =G7+G18 -> 0 | H29: =H7+H18 -> 0 | I29: =I7+I18 -> 0 | J29: =J7+J18 -> 0 | ... L29: =L7+L18 -> 0
B31: Contribution Margin by Property
B32: =$B$8 -> Aires de Campestre Apto 801 (Penthouse)
B33: Rental revenue | C33: =C8 -> 25517.025 | D33: =D8 -> 60811.625 | E33: =E8 -> 26681.485 | F33: =F8 -> 0 | G33: =G8 -> 0 | H33: =H8 -> 0 | I33: =I8 -> 0 | J33: =J8 -> 0 | ... L33: =L8 -> 0
B34: Property sale (gross) | C34: =C19 -> 0 | D34: =D19 -> 0 | E34: =E19 -> 2019763.4 | F34: =F19 -> 0 | G34: =G19 -> 0 | H34: =H19 -> 0 | I34: =I19 -> 0 | J34: =J19 -> 0 | ... L34: =L19 -> 0
B35: Less: housekeeping & turnover | C35: ='Property Detail'!C14 -> 0 | D35: ='Property Detail'!D14 -> 0 | E35: ='Property Detail'!E14 -> 0 | F35: ='Property Detail'!F14 -> 0 | G35: ='Property Detail'!G14 -> 0 | H35: ='Property Detail'!H14 -> 0 | I35: ='Property Detail'!I14 -> 0 | J35: ='Property Detail'!J14 -> 0 | ... L35: ='Property Detail'!L14 -> 0
B36: Less: property management & housekeeping | C36: ='Property Detail'!C16 -> 5103.405 | D36: ='Property Detail'!D16 -> 12162.325 | E36: ='Property Detail'!E16 -> 5336.2969 | F36: ='Property Detail'!F16 -> 0 | G36: ='Property Detail'!G16 -> 0 | H36: ='Property Detail'!H16 -> 0 | I36: ='Property Detail'!I16 -> 0 | J36: ='Property Detail'!J16 -> 0 | ... L36: ='Property Detail'!L16 -> 0
B37: Less: STR revenue taxes (ICA, FONTUR) | C37: ='Property Detail'!C15 -> 318.96281 | D37: ='Property Detail'!D15 -> 760.14531 | E37: ='Property Detail'!E15 -> 333.51856 | F37: ='Property Detail'!F15 -> 0 | G37: ='Property Detail'!G15 -> 0 | H37: ='Property Detail'!H15 -> 0 | I37: ='Property Detail'!I15 -> 0 | J37: ='Property Detail'!J15 -> 0 | ... L37: ='Property Detail'!L15 -> 0
B38: Less: cost basis released on sale | C38: =SUMIF('_Month Engine'!$C$5:$DR$5,C$4,'_Month Engine'!$C$73:$DR$73) -> 0 | D38: =SUMIF('_Month Engine'!$C$5:$DR$5,D$4,'_Month Engine'!$C$73:$DR$73) -> 0 | E38: =SUMIF('_Month Engine'!$C$5:$DR$5,E$4,'_Month Engine'!$C$73:$DR$73) -> 1168770.2 | F38: =SUMIF('_Month Engine'!$C$5:$DR$5,F$4,'_Month Engine'!$C$73:$DR$73) -> 0 | G38: =SUMIF('_Month Engine'!$C$5:$DR$5,G$4,'_Month Engine'!$C$73:$DR$73) -> 0 | H38: =SUMIF('_Month Engine'!$C$5:$DR$5,H$4,'_Month Engine'!$C$73:$DR$73) -> 0 | I38: =SUMIF('_Month Engine'!$C$5:$DR$5,I$4,'_Month Engine'!$C$73:$DR$73) -> 0 | J38: =SUMIF('_Month Engine'!$C$5:$DR$5,J$4,'_Month Engine'!$C$73:$DR$73) -> 0 | ... L38: =SUMIF('_Month Engine'!$C$5:$DR$5,L$4,'_Month Engine'!$C$73:$DR$73) -> 0
B39: Less: selling costs | C39: =C34*Input!$C$15 -> 0 | D39: =D34*Input!$C$15 -> 0 | E39: =E34*Input!$C$15 -> 76751.008 | F39: =F34*Input!$C$15 -> 0 | G39: =G34*Input!$C$15 -> 0 | H39: =H34*Input!$C$15 -> 0 | I39: =I34*Input!$C$15 -> 0 | J39: =J34*Input!$C$15 -> 0 | ... L39: =L34*Input!$C$15 -> 0
B40: Contribution margin | C40: =C33+C34-SUM(C35:C39) -> 20094.657 | D40: =D33+D34-SUM(D35:D39) -> 47889.155 | E40: =E33+E34-SUM(E35:E39) -> 795253.79 | F40: =F33+F34-SUM(F35:F39) -> 0 | G40: =G33+G34-SUM(G35:G39) -> 0 | H40: =H33+H34-SUM(H35:H39) -> 0 | I40: =I33+I34-SUM(I35:I39) -> 0 | J40: =J33+J34-SUM(J35:J39) -> 0 | ... L40: =L33+L34-SUM(L35:L39) -> 0
B41: CM % of revenue | C41: =IF(C33+C34=0,0,C40/(C33+C34)) -> 0.7875 | D41: =IF(D33+D34=0,0,D40/(D33+D34)) -> 0.7875 | E41: =IF(E33+E34=0,0,E40/(E33+E34)) -> 0.3886026 | F41: =IF(F33+F34=0,0,F40/(F33+F34)) -> 0 | G41: =IF(G33+G34=0,0,G40/(G33+G34)) -> 0 | H41: =IF(H33+H34=0,0,H40/(H33+H34)) -> 0 | I41: =IF(I33+I34=0,0,I40/(I33+I34)) -> 0 | J41: =IF(J33+J34=0,0,J40/(J33+J34)) -> 0 | ... L41: =IF(L33+L34=0,0,L40/(L33+L34)) -> 0
B42: Less: direct fixed costs | C42: =SUM('Property Detail'!C9:C13)+'Property Detail'!C17 -> 21836.94 | D42: =SUM('Property Detail'!D9:D13)+'Property Detail'!D17 -> 27965.939 | E42: =SUM('Property Detail'!E9:E13)+'Property Detail'!E17 -> 11652.474 | F42: =SUM('Property Detail'!F9:F13)+'Property Detail'!F17 -> 0 | G42: =SUM('Property Detail'!G9:G13)+'Property Detail'!G17 -> 0 | H42: =SUM('Property Detail'!H9:H13)+'Property Detail'!H17 -> 0 | I42: =SUM('Property Detail'!I9:I13)+'Property Detail'!I17 -> 0 | J42: =SUM('Property Detail'!J9:J13)+'Property Detail'!J17 -> 0 | ... L42: =SUM('Property Detail'!L9:L13)+'Property Detail'!L17 -> 0
...

Sheet Statement of Cash Flows
B1: Dulcinea — Statement of Cash Flows (USD)
B2: Indirect method. See Notes to Financials.
B4: Model year | C4: =COLUMN()-2 -> 1 | D4: =COLUMN()-2 -> 2 | E4: =COLUMN()-2 -> 3 | F4: =COLUMN()-2 -> 4 | G4: =COLUMN()-2 -> 5 | H4: =COLUMN()-2 -> 6 | I4: =COLUMN()-2 -> 7 | J4: =COLUMN()-2 -> 8 | ... L4: =COLUMN()-2 -> 10
B5: Period | C5: =TEXT(EDATE(Input!$C$7,(C4-1)*12),"mmm-yy")&" – "&TEXT(EDATE(Input!$C$7,C4*12-1),"mmm-yy") -> Oct-26 – Sep-27 | D5: =TEXT(EDATE(Input!$C$7,(D4-1)*12),"mmm-yy")&" – "&TEXT(EDATE(Input!$C$7,D4*12-1),"mmm-yy") -> Oct-27 – Sep-28 | E5: =TEXT(EDATE(Input!$C$7,(E4-1)*12),"mmm-yy")&" – "&TEXT(EDATE(Input!$C$7,E4*12-1),"mmm-yy") -> Oct-28 – Sep-29 | F5: =TEXT(EDATE(Input!$C$7,(F4-1)*12),"mmm-yy")&" – "&TEXT(EDATE(Input!$C$7,F4*12-1),"mmm-yy") -> Oct-29 – Sep-30 | G5: =TEXT(EDATE(Input!$C$7,(G4-1)*12),"mmm-yy")&" – "&TEXT(EDATE(Input!$C$7,G4*12-1),"mmm-yy") -> Oct-30 – Sep-31 | H5: =TEXT(EDATE(Input!$C$7,(H4-1)*12),"mmm-yy")&" – "&TEXT(EDATE(Input!$C$7,H4*12-1),"mmm-yy") -> Oct-31 – Sep-32 | I5: =TEXT(EDATE(Input!$C$7,(I4-1)*12),"mmm-yy")&" – "&TEXT(EDATE(Input!$C$7,I4*12-1),"mmm-yy") -> Oct-32 – Sep-33 | J5: =TEXT(EDATE(Input!$C$7,(J4-1)*12),"mmm-yy")&" – "&TEXT(EDATE(Input!$C$7,J4*12-1),"mmm-yy") -> Oct-33 – Sep-34 | ... L5: =TEXT(EDATE(Input!$C$7,(L4-1)*12),"mmm-yy")&" – "&TEXT(EDATE(Input!$C$7,L4*12-1),"mmm-yy") -> Oct-35 – Sep-36
B6: Cash Flow from Operating Activities
B7: Net income | C7: ='Income Statement'!C155 -> -126083.61 | D7: ='Income Statement'!D155 -> 1968.2859 | E7: ='Income Statement'!E155 -> 1837337.1 | F7: ='Income Statement'!F155 -> 1945121.1 | G7: ='Income Statement'!G155 -> 0 | H7: ='Income Statement'!H155 -> 0 | I7: ='Income Statement'!I155 -> 0 | J7: ='Income Statement'!J155 -> 0 | ... L7: ='Income Statement'!L155 -> 0
A8: 1 | B8: {=IF(Properties!$D$6=0,"",INDEX(Properties!$E:$E,$A8+5))} -> Aires de Campestre Apto 801 (Penthouse) | C8: =SUMIF('_Month Engine'!$C$5:$DR$5,C$4,INDEX('_Month Engine'!$C:$DR,MATCH("Cost Basis Released on Sale",'_Month Engine'!$A:$A,0)+MATCH($A8,'_Month Engine'!$B$73:$B$82,0),0)) -> 0 | D8: =SUMIF('_Month Engine'!$C$5:$DR$5,D$4,INDEX('_Month Engine'!$C:$DR,MATCH("Cost Basis Released on Sale",'_Month Engine'!$A:$A,0)+MATCH($A8,'_Month Engine'!$B$73:$B$82,0),0)) -> 0 | E8: =SUMIF('_Month Engine'!$C$5:$DR$5,E$4,INDEX('_Month Engine'!$C:$DR,MATCH("Cost Basis Released on Sale",'_Month Engine'!$A:$A,0)+MATCH($A8,'_Month Engine'!$B$73:$B$82,0),0)) -> 1168770.2 | F8: =SUMIF('_Month Engine'!$C$5:$DR$5,F$4,INDEX('_Month Engine'!$C:$DR,MATCH("Cost Basis Released on Sale",'_Month Engine'!$A:$A,0)+MATCH($A8,'_Month Engine'!$B$73:$B$82,0),0)) -> 0 | G8: =SUMIF('_Month Engine'!$C$5:$DR$5,G$4,INDEX('_Month Engine'!$C:$DR,MATCH("Cost Basis Released on Sale",'_Month Engine'!$A:$A,0)+MATCH($A8,'_Month Engine'!$B$73:$B$82,0),0)) -> 0 | H8: =SUMIF('_Month Engine'!$C$5:$DR$5,H$4,INDEX('_Month Engine'!$C:$DR,MATCH("Cost Basis Released on Sale",'_Month Engine'!$A:$A,0)+MATCH($A8,'_Month Engine'!$B$73:$B$82,0),0)) -> 0 | I8: =SUMIF('_Month Engine'!$C$5:$DR$5,I$4,INDEX('_Month Engine'!$C:$DR,MATCH("Cost Basis Released on Sale",'_Month Engine'!$A:$A,0)+MATCH($A8,'_Month Engine'!$B$73:$B$82,0),0)) -> 0 | J8: =SUMIF('_Month Engine'!$C$5:$DR$5,J$4,INDEX('_Month Engine'!$C:$DR,MATCH("Cost Basis Released on Sale",'_Month Engine'!$A:$A,0)+MATCH($A8,'_Month Engine'!$B$73:$B$82,0),0)) -> 0 | ... L8: =SUMIF('_Month Engine'!$C$5:$DR$5,L$4,INDEX('_Month Engine'!$C:$DR,MATCH("Cost Basis Released on Sale",'_Month Engine'!$A:$A,0)+MATCH($A8,'_Month Engine'!$B$73:$B$82,0),0)) -> 0
A9: 2 | B9: {=IF(Properties!$D$7=0,"",INDEX(Properties!$E:$E,$A9+5))} -> Fontanar Apto 201 (Penthouse) | C9: =SUMIF('_Month Engine'!$C$5:$DR$5,C$4,INDEX('_Month Engine'!$C:$DR,MATCH("Cost Basis Released on Sale",'_Month Engine'!$A:$A,0)+MATCH($A9,'_Month Engine'!$B$73:$B$82,0),0)) -> 0 | D9: =SUMIF('_Month Engine'!$C$5:$DR$5,D$4,INDEX('_Month Engine'!$C:$DR,MATCH("Cost Basis Released on Sale",'_Month Engine'!$A:$A,0)+MATCH($A9,'_Month Engine'!$B$73:$B$82,0),0)) -> 0 | E9: =SUMIF('_Month Engine'!$C$5:$DR$5,E$4,INDEX('_Month Engine'!$C:$DR,MATCH("Cost Basis Released on Sale",'_Month Engine'!$A:$A,0)+MATCH($A9,'_Month Engine'!$B$73:$B$82,0),0)) -> 1290857.6 | F9: =SUMIF('_Month Engine'!$C$5:$DR$5,F$4,INDEX('_Month Engine'!$C:$DR,MATCH("Cost Basis Released on Sale",'_Month Engine'!$A:$A,0)+MATCH($A9,'_Month Engine'!$B$73:$B$82,0),0)) -> 0 | G9: =SUMIF('_Month Engine'!$C$5:$DR$5,G$4,INDEX('_Month Engine'!$C:$DR,MATCH("Cost Basis Released on Sale",'_Month Engine'!$A:$A,0)+MATCH($A9,'_Month Engine'!$B$73:$B$82,0),0)) -> 0 | H9: =SUMIF('_Month Engine'!$C$5:$DR$5,H$4,INDEX('_Month Engine'!$C:$DR,MATCH("Cost Basis Released on Sale",'_Month Engine'!$A:$A,0)+MATCH($A9,'_Month Engine'!$B$73:$B$82,0),0)) -> 0 | I9: =SUMIF('_Month Engine'!$C$5:$DR$5,I$4,INDEX('_Month Engine'!$C:$DR,MATCH("Cost Basis Released on Sale",'_Month Engine'!$A:$A,0)+MATCH($A9,'_Month Engine'!$B$73:$B$82,0),0)) -> 0 | J9: =SUMIF('_Month Engine'!$C$5:$DR$5,J$4,INDEX('_Month Engine'!$C:$DR,MATCH("Cost Basis Released on Sale",'_Month Engine'!$A:$A,0)+MATCH($A9,'_Month Engine'!$B$73:$B$82,0),0)) -> 0 | ... L9: =SUMIF('_Month Engine'!$C$5:$DR$5,L$4,INDEX('_Month Engine'!$C:$DR,MATCH("Cost Basis Released on Sale",'_Month Engine'!$A:$A,0)+MATCH($A9,'_Month Engine'!$B$73:$B$82,0),0)) -> 0
A10: 3 | B10: {=IF(Properties!$D$8=0,"",INDEX(Properties!$E:$E,$A10+5))} -> San Lucas Apto 101 | C10: =SUMIF('_Month Engine'!$C$5:$DR$5,C$4,INDEX('_Month Engine'!$C:$DR,MATCH("Cost Basis Released on Sale",'_Month Engine'!$A:$A,0)+MATCH($A10,'_Month Engine'!$B$73:$B$82,0),0)) -> 0 | D10: =SUMIF('_Month Engine'!$C$5:$DR$5,D$4,INDEX('_Month Engine'!$C:$DR,MATCH("Cost Basis Released on Sale",'_Month Engine'!$A:$A,0)+MATCH($A10,'_Month Engine'!$B$73:$B$82,0),0)) -> 0 | E10: =SUMIF('_Month Engine'!$C$5:$DR$5,E$4,INDEX('_Month Engine'!$C:$DR,MATCH("Cost Basis Released on Sale",'_Month Engine'!$A:$A,0)+MATCH($A10,'_Month Engine'!$B$73:$B$82,0),0)) -> 747370.55 | F10: =SUMIF('_Month Engine'!$C$5:$DR$5,F$4,INDEX('_Month Engine'!$C:$DR,MATCH("Cost Basis Released on Sale",'_Month Engine'!$A:$A,0)+MATCH($A10,'_Month Engine'!$B$73:$B$82,0),0)) -> 0 | G10: =SUMIF('_Month Engine'!$C$5:$DR$5,G$4,INDEX('_Month Engine'!$C:$DR,MATCH("Cost Basis Released on Sale",'_Month Engine'!$A:$A,0)+MATCH($A10,'_Month Engine'!$B$73:$B$82,0),0)) -> 0 | H10: =SUMIF('_Month Engine'!$C$5:$DR$5,H$4,INDEX('_Month Engine'!$C:$DR,MATCH("Cost Basis Released on Sale",'_Month Engine'!$A:$A,0)+MATCH($A10,'_Month Engine'!$B$73:$B$82,0),0)) -> 0 | I10: =SUMIF('_Month Engine'!$C$5:$DR$5,I$4,INDEX('_Month Engine'!$C:$DR,MATCH("Cost Basis Released on Sale",'_Month Engine'!$A:$A,0)+MATCH($A10,'_Month Engine'!$B$73:$B$82,0),0)) -> 0 | J10: =SUMIF('_Month Engine'!$C$5:$DR$5,J$4,INDEX('_Month Engine'!$C:$DR,MATCH("Cost Basis Released on Sale",'_Month Engine'!$A:$A,0)+MATCH($A10,'_Month Engine'!$B$73:$B$82,0),0)) -> 0 | ... L10: =SUMIF('_Month Engine'!$C$5:$DR$5,L$4,INDEX('_Month Engine'!$C:$DR,MATCH("Cost Basis Released on Sale",'_Month Engine'!$A:$A,0)+MATCH($A10,'_Month Engine'!$B$73:$B$82,0),0)) -> 0
A11: 4 | B11: {=IF(Properties!$D$9=0,"",INDEX(Properties!$E:$E,$A11+5))} -> Casa Montana Lote 2 (Samuel Gaviria House) | C11: =SUMIF('_Month Engine'!$C$5:$DR$5,C$4,INDEX('_Month Engine'!$C:$DR,MATCH("Cost Basis Released on Sale",'_Month Engine'!$A:$A,0)+MATCH($A11,'_Month Engine'!$B$73:$B$82,0),0)) -> 0 | D11: =SUMIF('_Month Engine'!$C$5:$DR$5,D$4,INDEX('_Month Engine'!$C:$DR,MATCH("Cost Basis Released on Sale",'_Month Engine'!$A:$A,0)+MATCH($A11,'_Month Engine'!$B$73:$B$82,0),0)) -> 0 | E11: =SUMIF('_Month Engine'!$C$5:$DR$5,E$4,INDEX('_Month Engine'!$C:$DR,MATCH("Cost Basis Released on Sale",'_Month Engine'!$A:$A,0)+MATCH($A11,'_Month Engine'!$B$73:$B$82,0),0)) -> 0 | F11: =SUMIF('_Month Engine'!$C$5:$DR$5,F$4,INDEX('_Month Engine'!$C:$DR,MATCH("Cost Basis Released on Sale",'_Month Engine'!$A:$A,0)+MATCH($A11,'_Month Engine'!$B$73:$B$82,0),0)) -> 1714482.2 | G11: =SUMIF('_Month Engine'!$C$5:$DR$5,G$4,INDEX('_Month Engine'!$C:$DR,MATCH("Cost Basis Released on Sale",'_Month Engine'!$A:$A,0)+MATCH($A11,'_Month Engine'!$B$73:$B$82,0),0)) -> 0 | H11: =SUMIF('_Month Engine'!$C$5:$DR$5,H$4,INDEX('_Month Engine'!$C:$DR,MATCH("Cost Basis Released on Sale",'_Month Engine'!$A:$A,0)+MATCH($A11,'_Month Engine'!$B$73:$B$82,0),0)) -> 0 | I11: =SUMIF('_Month Engine'!$C$5:$DR$5,I$4,INDEX('_Month Engine'!$C:$DR,MATCH("Cost Basis Released on Sale",'_Month Engine'!$A:$A,0)+MATCH($A11,'_Month Engine'!$B$73:$B$82,0),0)) -> 0 | J11: =SUMIF('_Month Engine'!$C$5:$DR$5,J$4,INDEX('_Month Engine'!$C:$DR,MATCH("Cost Basis Released on Sale",'_Month Engine'!$A:$A,0)+MATCH($A11,'_Month Engine'!$B$73:$B$82,0),0)) -> 0 | ... L11: =SUMIF('_Month Engine'!$C$5:$DR$5,L$4,INDEX('_Month Engine'!$C:$DR,MATCH("Cost Basis Released on Sale",'_Month Engine'!$A:$A,0)+MATCH($A11,'_Month Engine'!$B$73:$B$82,0),0)) -> 0
